<?xml version="1.0" encoding="utf-8"?>
<mujoco>
    <compiler angle="radian" coordinate="local" meshdir="../stls/fetch" texturedir="../textures"></compiler>
    <size nconmax="1000"></size>
    <size njmax="1000"></size>
    <option timestep="0.002">
        <flag warmstart="enable"></flag>
    </option>


	<include file="shared.xml"></include>
	<asset>
        <material name="impenetrable" rgba="1 0 0 1"/>
        <material name="rubber" rgba="1 0.5 0 1"/>
    </asset>
    
	
	<worldbody>
		<geom name="floor0" pos="0.8 0.75 0" size="0.85 0.7 1" type="plane" condim="3" material="floor_mat"></geom>
		<body name="floor0" pos="0.8 0.75 0">
			<site name="target0" pos="0 0 0.5" size="0.02 0.02 0.02" rgba="1 0 0 1" type="sphere"></site>
		</body>
        
		<include file="robot.xml"></include>
		
		<body pos="1.3 0.75 0.2" name="table0">
			<geom size="0.25 0.35 0.2" type="box" mass="2000" material="table_mat"></geom>
		</body>
	
		<body name="goal" pos="0 0.6 0.4">
            <geom mass="5000" condim="3" pos="0 0 0" size="0.04 0.05 0.008" type="box" group="0" rgba="0.8 0 0 1" friction="1"/> 
            <geom mass="5000" condim="3" pos="0 0.05 0.01325" size="0.04 0.001 0.0055" type="box" group="0" rgba="0.8 0 0 1" friction="1" />  <!-- fence-->
            <geom mass="5000" condim="3" pos="0 -0.05 0.01325" size="0.04 0.001 0.0055" type="box" group="0" rgba="0.8 0 0 1" friction="1"/> <!-- fence-->
            <geom mass="5000" condim="3" pos="0.04 0 0.01325" size="0.001 0.05 0.0055" type="box" group="0" rgba="0.8 0 0 1" friction="1"/> <!-- fence-->
            <geom mass="5000" condim="3" pos="-0.04 0 0.01325" size="0.001 0.05 0.0055" type="box" group="0" rgba="0.8 0 0 1" friction="1"/> <!-- fence-->
            <joint axis="1 0 0" name="goal:slidex" type="slide"/> 
            <joint axis="0 1 0" name="goal:slidey" type="slide"/>
        <joint name="goal:ball" type="ball" pos="0 0 0"/>
        <site name="goal" pos="0 0 0" size="0.002 0.002 0.002" rgba="1 0 0 1" type="sphere"></site>
        </body>
        
        <body name="tray" pos="0 0 0.4">
            <geom mass="5000" condim="3" pos="0 0 0" size="0.04 0.05 0.008" type="box" group="0" rgba="0 0.8 0 1" friction="1"/> 
            <geom mass="5000" condim="3" pos="0 0.05 0.01325" size="0.04 0.001 0.0055" type="box" group="0" rgba="0 0.8 0 1" friction="1" />  <!-- fence-->
            <geom mass="5000" condim="3" pos="0 -0.05 0.01325" size="0.04 0.001 0.0055" type="box" group="0" rgba="0 0.8 0 1" friction="1"/> <!-- fence-->
            <geom mass="5000" condim="3" pos="0.04 0 0.01325" size="0.001 0.05 0.0055" type="box" group="0" rgba="0 0.8 0 1" friction="1"/> <!-- fence-->
            <geom mass="5000" condim="3" pos="-0.04 0 0.01325" size="0.001 0.05 0.0055" type="box" group="0" rgba="0 0.8 0 1" friction="1"/> <!-- fence-->
            <joint axis="1 0 0" name="tray:slidex" type="slide"/> 
            <joint axis="0 1 0" name="tray:slidey" type="slide"/>
            <joint name="tray:ball" type="ball" pos="0 0 0"/>
            <site name="tray" pos="0 0 0" size="0.002 0.002 0.002" rgba="1 0 0 1" type="sphere"></site>
        </body>



		<body name="object0" pos= "0 0.61 0.48"> <!--"0.025 0.025 0.025"--> 
            <joint name="object0:joint" type="free"></joint>
            <!--joint name="object0:ball" type="ball" pos="0 0 0"/-->
            <geom size="0.025 0.025 0.035" type="box" condim="3" name="object0" mass="10" rgba="0 0 0.8 1" solref="0.02 1" solimp="0.9 0.95 0.001" friction="1"></geom>
            <site name="object0" pos="0 0 0" size="0.02 0.02 0.02" rgba="1 0 0 1" type="sphere"></site>
        </body>

		

		<light directional="true" ambient="0.2 0.2 0.2" diffuse="0.8 0.8 0.8" specular="0.3 0.3 0.3" castshadow="false" pos="0 0 4" dir="0 0 -1" name="light0"></light>
		<camera name="view1" pos="0 4.0 1.3" quat="1.22206e-06 -5.16678e-07 0.389418 0.921061" />
	</worldbody>

	<actuator>
		<position ctrllimited="true" ctrlrange="0 0.2" joint="robot0:l_gripper_finger_joint" kp="80000" name="robot0:l_gripper_finger_joint" user="1"></position>
		<position ctrllimited="true" ctrlrange="0 0.2" joint="robot0:r_gripper_finger_joint" kp="80000" name="robot0:r_gripper_finger_joint" user="1"></position>
	</actuator>
</mujoco>
